Workbook

Sheet 00_Huong dan
B2: HƯỚNG DẪN SỬ DỤNG – HỆ THỐNG KIỂM SOÁT KHÉP KÍN VÒNG ĐỜI GÓI THẦU (v1)
B4: 1. BẢN ĐỒ SHEET
B5: • BANG TONG HOP: bảng xương sống – mỗi hạng mục 1 dòng, đi từ đầu vào CĐT → KHCU → KHTK → cổng khởi công → quản lý sau khởi công → cảnh báo.
B6: • 01_HSo TienKC: sổ lưu LINK sản phẩm các bước tiền khởi công đã hoàn thành (HSTKTC, SPECS, BOQ, KQ LCNT, HĐCU, KHCU, PLHĐ, KHTK).
B7: • 02_KH Thang_Tuan: kế hoạch triển khai theo tháng – 5 tài liệu bắt buộc (BPTC, KH cung ứng, biểu đồ nhân lực, biểu đồ máy móc thiết bị, biểu đồ cung ứng) + lập/duyệt.
B8: • 03_Phat sinh: phát sinh & sai khác – làm rõ, ghi nhận, phê duyệt, cập nhật điều chỉnh (KH→KQ).
B9: • 04_CU dac thu: yêu cầu cung ứng đặc thù/đột xuất – ghi nhận, phê duyệt, kiểm soát.
B10: • 05_Bu tien do: phương án bù tiến độ khi chậm (tăng ca, đổi BPTC, thêm nguồn lực).
B11: • DM_Danh muc: danh mục chuẩn cho dropdown. • DASHBOARD: tổng hợp tự động.
B13: 2. KHÓA LIÊN KẾT = MÃ BSC
B14: Mọi sổ đều có cột 'Mã BSC' trỏ về hạng mục trong BANG TONG HOP. Master tự đếm ngược từ các sổ (cột F: tài liệu tháng, phát sinh, cung ứng đột xuất, bù tiến độ) → tạo vòng khép kín 'link về tổng thể'.
B16: 3. QUY TẮC NHẬP LIỆU (đã chuẩn hóa)
... B33: CHUỖI MẪU: hạng mục CT-01 (Nhà mẫu) đã được đẩy chạy hết vòng đời (đủ ĐK → khởi công 01/06/2026 → báo cáo tháng 6 → có phát sinh, cung ứng đột xuất, bù tiến độ) để minh họa toàn hệ.

Sheet DASHBOARD
B2: DASHBOARD ĐIỀU HÀNH – TỰ ĐỘNG TỪ TOÀN HỆ THỐNG
B3: (Làm mới khi mở/recalc. Vùng master: dòng 6–40; vùng sổ: dòng 3–100)
B5: ① TIỀN KHỞI CÔNG (chốt chặn)
B6: Tổng hạng mục có Mã theo dõi | C6: =COUNTA('BANG TONG HOP'!B6:B45) -> 3
B7: Đủ ĐK khởi công | C7: =COUNTIF('BANG TONG HOP'!AC6:AC45,"ĐỦ ĐK*") -> 2
B8: Thiếu ĐK khởi công | C8: =COUNTIF('BANG TONG HOP'!AC6:AC45,"THIẾU*") -> 1
B9: Đã khởi công (có ngày BĐ) | C9: =COUNT('BANG TONG HOP'!AD6:AD45) -> 2
B10: Hồ sơ tiền KC đã lưu (sổ 01) | C10: =COUNTIF('01_HSo TienKC'!J3:J100,"Đã duyệt") -> 16
B12: ② SAU KHỞI CÔNG (báo cáo & kiểm soát)
B13: Tài liệu KH tháng đã duyệt / tổng (sổ 02) | C13: =COUNTIF('02_KH Thang_Tuan'!J3:J100,"Đã duyệt")&" / "&COUNTA('02_KH Thang_Tuan'!B3:B100) -> 4 / 5
B14: Phát sinh/sai khác chưa duyệt (sổ 03) | C14: =SUM('BANG TONG HOP'!AJ6:AJ45) -> 1
B15: YC cung ứng đột xuất chờ duyệt (sổ 04) | C15: =SUM('BANG TONG HOP'!AK6:AK45) -> 1
B16: Phương án bù tiến độ đang chạy (sổ 05) | C16: =SUM('BANG TONG HOP'!AL6:AL45) -> 1
B18: ③ CẢNH BÁO TỔNG HỢP
B19: Cảnh báo ĐỎ | C19: =COUNTIF('BANG TONG HOP'!#REF!,"ĐỎ*") -> #REF!
B20: Cảnh báo CAM | C20: =COUNTIF('BANG TONG HOP'!#REF!,"CAM*") -> #REF!
B21: Cảnh báo VÀNG | C21: =COUNTIF('BANG TONG HOP'!#REF!,"VÀNG*") -> #REF!
B22: Bình thường (XANH) | C22: =COUNTIF('BANG TONG HOP'!#REF!,"XANH*") -> #REF!
B23: Rủi ro mức Cao | C23: =COUNTIF('BANG TONG HOP'!#REF!,"Cao") -> #REF!
B25: ④ TÀI CHÍNH (tỷ VNĐ)
B26: Tổng ngân sách CĐT | C26: =SUM('BANG TONG HOP'!I6:I45) -> 177.3
B27: Tổng giá trị HĐCU | C27: =SUM('BANG TONG HOP'!T6:T45) -> 121.3
B28: Tổng giá trị phát sinh (sổ 03) | C28: =SUM('03_Phat sinh'!J3:J100) -> 0.8
B29: Tổng giá trị cung ứng đột xuất (sổ 04) | C29: =SUM('04_CU dac thu'!K3:K100) -> 1.25
B31: QUY TẮC VÀNG: Không HSTKTC → Không cung ứng + Không HDTC → Không thi công

Sheet BANG TONG HOP
A1: HỆ THỐNG KIỂM SOÁT KHÉP KÍN VÒNG ĐỜI GÓI THẦU THI CÔNG – BẢNG TỔNG HỢP (v1)
A2: Dự án KĐT Ven sông Vinh | Ô nền xám = công thức tự động | Cột F & G tự liên kết 5 sổ đăng ký | Chuỗi mẫu: CT-01 chạy hết vòng đời
A3: 0. ĐỊNH DANH | G3: A. ĐẦU VÀO CĐT (Tiến độ – Ngân sách – HSKT) | N3: B. KẾ HOẠCH CUNG ỨNG (KHCU) | V3: C. KẾ HOẠCH TRIỂN KHAI (KHTK) | Z3: D. CHỐT CHẶN ĐIỀU KIỆN KHỞI CÔNG | AF3: E. QUẢN LÝ NGÂN SÁCH THỰC HIỆN | AI3: THÁNG 06/2026
A4: TT | B4: Mã BSC | C4: Gói thầu (PL) | D4: Nhóm CT | E4: Hạng mục / Công việc | F4: Phụ trách | G4: Ngày BĐ (YC CĐT) | H4: Ngày KT (YC CĐT) | I4: Ngân sách (tỷ) | J4: KH phát hành HSTKTC | K4: TT HSTKTC | L4: TT SPECS | M4: TT BOQ/KL | N4: KH LCNT | O4: TT LCNT | P4: KH Ký HĐCU | Q4: TT Ký HĐCU | R4: KH PD KHCU | S4: TT KHCU | T4: Giá trị HĐCU (tỷ) | U4: % HĐCU/NS | V4: KH ký PLHĐ CĐT | W4: TT Ký PLHĐ CĐT | X4: KH PD KHTK | Y4: TT KHTK | Z4: ĐK1 HSKT đủ | AA4: ĐK2 HĐCU ký | AB4: ĐK3 KHTK duyệt | AC4: ĐIỀU KIỆN ĐỦ | AD4: NGÀY BĐ KHỞI CÔNG | AE4: HS tiền KC (duyệt) | AF4: LŨY KẾ GIÁ TRỊ HĐ A - B | AG4: LŨY KẾ PHÁT SINH HĐ B - B' | AH4: LŨY KẾ TỔNG CHI PHÍ/ NGÂN SÁCH | AI4: F. KIỂM SOÁT HỒ SƠ KHTK/ PHÁT SINH | AM4: G. QUẢN LÝ QA/QC/QS | AP4: G. QUẢN LÝ THI CÔNG | AS4: TUẦN 1 | AV4: TUẦN 2 | AY4: TUẦN 3 | BB4: TUẦN 4
AI5: Tài liệu KH tháng (duyệt/tổng) | AJ5: Phát sinh chưa duyệt | AK5: YC cung ứng chờ duyệt | AL5: Bù tiến độ đang chạy | AM5: KH KLCV tháng | AN5: KQ KLCV tháng | AO5: Đánh giá & giải pháp tháng | AP5: KH KLCV tháng | AQ5: KQ KLCV tháng | AR5: Đánh giá & giải pháp tháng | AS5: T1 KH | AT5: T1 KQ | AU5: T1 Đánh giá | AV5: T2 KH | AW5: T2 KQ | AX5: T2 Đánh giá | AY5: T3 KH | AZ5: T3 KQ | BA5: T3 Đánh giá | BB5: T4 KH | BC5: T4 KQ | BD5: T4 Đánh giá
A6: 1 | B6: HT-PL02-01 | C6: PL02 | D6: Hạ tầng kỹ thuật | E6: HTKT quanh CV + nhà mẫu (Giao thông) | F6: An Dương | G6: 45667 | H6: 46387 | I6: 35.3 | J6: 45627 | K6: Hoàn thiện | L6: Đã cấp | M6: Đã bàn giao | N6: 45636 | O6: Đã có KQ | P6: 45646 | Q6: Đã CU | R6: 45662 | S6: Đã duyệt | T6: 34.8 | U6: =IF(OR(I6="",T6=""),"",T6/I6) -> 0.98583569 | V6: 45663 | W6: Đã ký PLHĐ | X6: 45665 | Y6: Đã duyệt | Z6: =IF($B6="","",IF(AND(OR(K6="Đã phát hành",K6="Hoàn thiện"),M6="Đã bàn giao"),"✔","✘")) -> ✔ | AA6: =IF($B6="","",IF(Q6="Đã CU","✔","✘")) -> ✔ | AB6: =IF($B6="","",IF(Y6="Đã duyệt","✔","✘")) -> ✔ | AC6: =IF($B6="","",IF(AND(Z6="✔",AA6="✔",AB6="✔"),"ĐỦ ĐK KHỞI CÔNG","THIẾU ĐK")) -> ĐỦ ĐK KHỞI CÔNG | AD6: 45672 | AE6: =IF($B6="","",COUNTIFS('01_HSo TienKC'!$B:$B,$B6,'01_HSo TienKC'!$J:$J,"Đã duyệt")) -> 8 | AI6: =IF($B6="","",COUNTIFS('02_KH Thang_Tuan'!$B:$B,$B6,'02_KH Thang_Tuan'!$J:$J,"Đã duyệt")&"/"&COUNTIFS('02_KH Thang_Tuan'!$B:$B,$B6)) -> 0/0 | AJ6: =IF($B6="","",COUNTIFS('03_Phat sinh'!$C:$C,$B6,'03_Phat sinh'!$M:$M,"<>Đã duyệt")) -> 0 | AK6: =IF($B6="","",COUNTIFS('04_CU dac thu'!$C:$C,$B6,'04_CU dac thu'!$N:$N,"<>Đã duyệt")) -> 0 | AL6: =IF($B6="","",COUNTIFS('05_Bu tien do'!$B:$B,$B6,'05_Bu tien do'!$N:$N,"<>Đã hoàn thành")) -> 0 | AM6: 0.95 | AN6: 0.95 | AO6: Đúng tiến độ, đang hoàn thiện vỉa hè | AP6: 0.95 | AQ6: 0.95 | AR6: Đúng tiến độ, đang hoàn thiện vỉa hè | AS6: 0.8 | AT6: 0.8 | AV6: 0.86 | AW6: 0.86 | AY6: 0.91 | AZ6: 0.91 | BB6: 0.95 | BC6: 0.95
A7: 2 | B7: VSV_QLTC_TT.01 | C7: PL10 | D7: Xây dựng dân dụng | E7: CT-01: Thi công & lắp đặt thiết bị Nhà mẫu | F7: HĐLCNT / Tổng thầu | G7: 46174 | H7: 46295 | I7: 100 | J7: 46162 | K7: Hoàn thiện | L7: Đã cấp | M7: Đã bàn giao | N7: 46152 | O7: Đã có KQ | P7: 46162 | Q7: Đã CU | R7: 46167 | S7: Đã duyệt | T7: 74.5 | U7: =IF(OR(I7="",T7=""),"",T7/I7) -> 0.745 | V7: 46164 | W7: Đã ký PLHĐ | X7: 46170 | Y7: Đã duyệt | Z7: =IF($B7="","",IF(AND(OR(K7="Đã phát hành",K7="Hoàn thiện"),M7="Đã bàn giao"),"✔","✘")) -> ✔ | AA7: =IF($B7="","",IF(Q7="Đã CU","✔","✘")) -> ✔ | AB7: =IF($B7="","",IF(Y7="Đã duyệt","✔","✘")) -> ✔ | AC7: =IF($B7="","",IF(AND(Z7="✔",AA7="✔",AB7="✔"),"ĐỦ ĐK KHỞI CÔNG","THIẾU ĐK")) -> ĐỦ ĐK KHỞI CÔNG | AD7: 46174 | AE7: =IF($B7="","",COUNTIFS('01_HSo TienKC'!$B:$B,$B7,'01_HSo TienKC'!$J:$J,"Đã duyệt")) -> 8 | AI7: =IF($B7="","",COUNTIFS('02_KH Thang_Tuan'!$B:$B,$B7,'02_KH Thang_Tuan'!$J:$J,"Đã duyệt")&"/"&COUNTIFS('02_KH Thang_Tuan'!$B:$B,$B7)) -> 4/5 | AJ7: =IF($B7="","",COUNTIFS('03_Phat sinh'!$C:$C,$B7,'03_Phat sinh'!$M:$M,"<>Đã duyệt")) -> 1 | AK7: =IF($B7="","",COUNTIFS('04_CU dac thu'!$C:$C,$B7,'04_CU dac thu'!$N:$N,"<>Đã duyệt")) -> 1 | AL7: =IF($B7="","",COUNTIFS('05_Bu tien do'!$B:$B,$B7,'05_Bu tien do'!$N:$N,"<>Đã hoàn thành")) -> 1 | AM7: 0.25 | AN7: 0.22 | AO7: Chậm nhẹ do mưa + nền yếu; đang bù tiến độ, dự kiến đạt cuối T4 | AP7: 0.25 | AQ7: 0.22 | AR7: Chậm nhẹ do mưa + nền yếu; đang bù tiến độ, dự kiến đạt cuối T4 | AS7: 0.06 | AT7: 0.06 | AV7: 0.12 | AW7: 0.11 | AX7: Thiếu nhân lực ca đêm | AY7: 0.19 | AZ7: 0.16 | BA7: Mưa + phát sinh nền yếu | BB7: 0.25 | BC7: 0.22 | BD7: Tăng ca bù KL
A8: 2.1 | C8: HM lớn | E8: Thi công cọc (thí nghiệm + đại trà) | I8: 10 | T8: 12 | U8: =IF(OR(I8="",T8=""),"",T8/I8) -> 1.2 | Z8: =IF($B8="","",IF(AND(OR(#REF!="Đã phát hành",#REF!="Hoàn thiện"),M8="Đã bàn giao"),"✔","✘")) | AA8: =IF($B8="","",IF(Q8="Đã CU","✔","✘")) | AB8: =IF($B8="","",IF(Y8="Đã duyệt","✔","✘")) | AC8: =IF($B8="","",IF(AND(Z8="✔",AA8="✔",AB8="✔"),"ĐỦ ĐK KHỞI CÔNG","THIẾU ĐK")) | AE8: =IF($B8="","",COUNTIFS('01_HSo TienKC'!$B:$B,$B8,'01_HSo TienKC'!$J:$J,"Đã duyệt")) | AI8: =IF($B8="","",COUNTIFS('02_KH Thang_Tuan'!$B:$B,$B8,'02_KH Thang_Tuan'!$J:$J,"Đã duyệt")&"/"&COUNTIFS('02_KH Thang_Tuan'!$B:$B,$B8)) | AJ8: =IF($B8="","",COUNTIFS('03_Phat sinh'!$C:$C,$B8,'03_Phat sinh'!$M:$M,"<>Đã duyệt")) | AK8: =IF($B8="","",COUNTIFS('04_CU dac thu'!$C:$C,$B8,'04_CU dac thu'!$N:$N,"<>Đã duyệt")) | AL8: =IF($B8="","",COUNTIFS('05_Bu tien do'!$B:$B,$B8,'05_Bu tien do'!$N:$N,"<>Đã hoàn thành"))
A9: 2.2 | C9: HM lớn | E9: Thi công móng, kết cấu thân, xây thô, trát sơn bả, chống thấm | I9: 20 | U9: =IF(OR(I9="",T9=""),"",T9/I9) | Z9: =IF($B9="","",IF(AND(OR(K8="Đã phát hành",K8="Hoàn thiện"),M9="Đã bàn giao"),"✔","✘")) | AA9: =IF($B9="","",IF(Q9="Đã CU","✔","✘")) | AB9: =IF($B9="","",IF(Y9="Đã duyệt","✔","✘")) | AC9: =IF($B9="","",IF(AND(Z9="✔",AA9="✔",AB9="✔"),"ĐỦ ĐK KHỞI CÔNG","THIẾU ĐK")) | AE9: =IF($B9="","",COUNTIFS('01_HSo TienKC'!$B:$B,$B9,'01_HSo TienKC'!$J:$J,"Đã duyệt")) | AI9: =IF($B9="","",COUNTIFS('02_KH Thang_Tuan'!$B:$B,$B9,'02_KH Thang_Tuan'!$J:$J,"Đã duyệt")&"/"&COUNTIFS('02_KH Thang_Tuan'!$B:$B,$B9)) | AJ9: =IF($B9="","",COUNTIFS('03_Phat sinh'!$C:$C,$B9,'03_Phat sinh'!$M:$M,"<>Đã duyệt")) | AK9: =IF($B9="","",COUNTIFS('04_CU dac thu'!$C:$C,$B9,'04_CU dac thu'!$N:$N,"<>Đã duyệt")) | AL9: =IF($B9="","",COUNTIFS('05_Bu tien do'!$B:$B,$B9,'05_Bu tien do'!$N:$N,"<>Đã hoàn thành"))
A10: 2.2.1 | C10: HM thành phần | E10: Thi công kết cấu thân | AJ10: =IF($B10="","",COUNTIFS('03_Phat sinh'!$C:$C,$B10,'03_Phat sinh'!$M:$M,"<>Đã duyệt")) | AK10: =IF($B10="","",COUNTIFS('04_CU dac thu'!$C:$C,$B10,'04_CU dac thu'!$N:$N,"<>Đã duyệt")) | AL10: =IF($B10="","",COUNTIFS('05_Bu tien do'!$B:$B,$B10,'05_Bu tien do'!$N:$N,"<>Đã hoàn thành"))
A11: 2.2.2 | C11: HM thành phần | E11: Thi công xây thô mặt ngoài | AJ11: =IF($B11="","",COUNTIFS('03_Phat sinh'!$C:$C,$B11,'03_Phat sinh'!$M:$M,"<>Đã duyệt")) | AK11: =IF($B11="","",COUNTIFS('04_CU dac thu'!$C:$C,$B11,'04_CU dac thu'!$N:$N,"<>Đã duyệt")) | AL11: =IF($B11="","",COUNTIFS('05_Bu tien do'!$B:$B,$B11,'05_Bu tien do'!$N:$N,"<>Đã hoàn thành"))
A12: 2.2.3 | C12: HM thành phần | E12: Thi công phần trát sơn bả mặt ngoài | AJ12: =IF($B12="","",COUNTIFS('03_Phat sinh'!$C:$C,$B12,'03_Phat sinh'!$M:$M,"<>Đã duyệt")) | AK12: =IF($B12="","",COUNTIFS('04_CU dac thu'!$C:$C,$B12,'04_CU dac thu'!$N:$N,"<>Đã duyệt")) | AL12: =IF($B12="","",COUNTIFS('05_Bu tien do'!$B:$B,$B12,'05_Bu tien do'!$N:$N,"<>Đã hoàn thành"))
A13: 2.2.4 | C13: HM thành phần | E13: Thi công chống thấm, san nền | AJ13: =IF($B13="","",COUNTIFS('03_Phat sinh'!$C:$C,$B13,'03_Phat sinh'!$M:$M,"<>Đã duyệt")) | AK13: =IF($B13="","",COUNTIFS('04_CU dac thu'!$C:$C,$B13,'04_CU dac thu'!$N:$N,"<>Đã duyệt")) | AL13: =IF($B13="","",COUNTIFS('05_Bu tien do'!$B:$B,$B13,'05_Bu tien do'!$N:$N,"<>Đã hoàn thành"))
A14: 2.2.5 | C14: HM thành phần | E14: Thi công thang bộ, hoàn thiện bên trong | AJ14: =IF($B14="","",COUNTIFS('03_Phat sinh'!$C:$C,$B14,'03_Phat sinh'!$M:$M,"<>Đã duyệt")) | AK14: =IF($B14="","",COUNTIFS('04_CU dac thu'!$C:$C,$B14,'04_CU dac thu'!$N:$N,"<>Đã duyệt")) | AL14: =IF($B14="","",COUNTIFS('05_Bu tien do'!$B:$B,$B14,'05_Bu tien do'!$N:$N,"<>Đã hoàn thành"))
A15: 2.3 | C15: HM lớn | E15: Thi công mái ngói, trần mặt ngoài | U15: =IF(OR(I15="",T15=""),"",T15/I15) | Z15: =IF($B15="","",IF(AND(OR(K15="Đã phát hành",K15="Hoàn thiện"),M15="Đã bàn giao"),"✔","✘")) | AA15: =IF($B15="","",IF(Q15="Đã CU","✔","✘")) | AB15: =IF($B15="","",IF(Y15="Đã duyệt","✔","✘")) | AC15: =IF($B15="","",IF(AND(Z15="✔",AA15="✔",AB15="✔"),"ĐỦ ĐK KHỞI CÔNG","THIẾU ĐK")) | AE15: =IF($B15="","",COUNTIFS('01_HSo TienKC'!$B:$B,$B15,'01_HSo TienKC'!$J:$J,"Đã duyệt")) | AI15: =IF($B15="","",COUNTIFS('02_KH Thang_Tuan'!$B:$B,$B15,'02_KH Thang_Tuan'!$J:$J,"Đã duyệt")&"/"&COUNTIFS('02_KH Thang_Tuan'!$B:$B,$B15)) | AJ15: =IF($B15="","",COUNTIFS('03_Phat sinh'!$C:$C,$B15,'03_Phat sinh'!$M:$M,"<>Đã duyệt")) | AK15: =IF($B15="","",COUNTIFS('04_CU dac thu'!$C:$C,$B15,'04_CU dac thu'!$N:$N,"<>Đã duyệt")) | AL15: =IF($B15="","",COUNTIFS('05_Bu tien do'!$B:$B,$B15,'05_Bu tien do'!$N:$N,"<>Đã hoàn thành"))
A16: 2.4 | C16: HM lớn | E16: Thi công hàng rào | U16: =IF(OR(I16="",T16=""),"",T16/I16) | Z16: =IF($B16="","",IF(AND(OR(K16="Đã phát hành",K16="Hoàn thiện"),M16="Đã bàn giao"),"✔","✘")) | AA16: =IF($B16="","",IF(Q16="Đã CU","✔","✘")) | AB16: =IF($B16="","",IF(Y16="Đã duyệt","✔","✘")) | AC16: =IF($B16="","",IF(AND(Z16="✔",AA16="✔",AB16="✔"),"ĐỦ ĐK KHỞI CÔNG","THIẾU ĐK")) | AE16: =IF($B16="","",COUNTIFS('01_HSo TienKC'!$B:$B,$B16,'01_HSo TienKC'!$J:$J,"Đã duyệt")) | AI16: =IF($B16="","",COUNTIFS('02_KH Thang_Tuan'!$B:$B,$B16,'02_KH Thang_Tuan'!$J:$J,"Đã duyệt")&"/"&COUNTIFS('02_KH Thang_Tuan'!$B:$B,$B16)) | AJ16: =IF($B16="","",COUNTIFS('03_Phat sinh'!$C:$C,$B16,'03_Phat sinh'!$M:$M,"<>Đã duyệt")) | AK16: =IF($B16="","",COUNTIFS('04_CU dac thu'!$C:$C,$B16,'04_CU dac thu'!$N:$N,"<>Đã duyệt")) | AL16: =IF($B16="","",COUNTIFS('05_Bu tien do'!$B:$B,$B16,'05_Bu tien do'!$N:$N,"<>Đã hoàn thành"))
A17: 2.5 | C17: HM lớn | E17: Thi công lan can ban công | U17: =IF(OR(I17="",T17=""),"",T17/I17) | Z17: =IF($B17="","",IF(AND(OR(K17="Đã phát hành",K17="Hoàn thiện"),M17="Đã bàn giao"),"✔","✘")) | AA17: =IF($B17="","",IF(Q17="Đã CU","✔","✘")) | AB17: =IF($B17="","",IF(Y17="Đã duyệt","✔","✘")) | AC17: =IF($B17="","",IF(AND(Z17="✔",AA17="✔",AB17="✔"),"ĐỦ ĐK KHỞI CÔNG","THIẾU ĐK")) | AE17: =IF($B17="","",COUNTIFS('01_HSo TienKC'!$B:$B,$B17,'01_HSo TienKC'!$J:$J,"Đã duyệt")) | AI17: =IF($B17="","",COUNTIFS('02_KH Thang_Tuan'!$B:$B,$B17,'02_KH Thang_Tuan'!$J:$J,"Đã duyệt")&"/"&COUNTIFS('02_KH Thang_Tuan'!$B:$B,$B17)) | AJ17: =IF($B17="","",COUNTIFS('03_Phat sinh'!$C:$C,$B17,'03_Phat sinh'!$M:$M,"<>Đã duyệt")) | AK17: =IF($B17="","",COUNTIFS('04_CU dac thu'!$C:$C,$B17,'04_CU dac thu'!$N:$N,"<>Đã duyệt")) | AL17: =IF($B17="","",COUNTIFS('05_Bu tien do'!$B:$B,$B17,'05_Bu tien do'!$N:$N,"<>Đã hoàn thành"))
A18: 2.6 | C18: HM lớn | E18: Thi công lam gỗ mặt ngoài | U18: =IF(OR(I18="",T18=""),"",T18/I18) | Z18: =IF($B18="","",IF(AND(OR(K18="Đã phát hành",K18="Hoàn thiện"),M18="Đã bàn giao"),"✔","✘")) | AA18: =IF($B18="","",IF(Q18="Đã CU","✔","✘")) | AB18: =IF($B18="","",IF(Y18="Đã duyệt","✔","✘")) | AC18: =IF($B18="","",IF(AND(Z18="✔",AA18="✔",AB18="✔"),"ĐỦ ĐK KHỞI CÔNG","THIẾU ĐK")) | AE18: =IF($B18="","",COUNTIFS('01_HSo TienKC'!$B:$B,$B18,'01_HSo TienKC'!$J:$J,"Đã duyệt")) | AI18: =IF($B18="","",COUNTIFS('02_KH Thang_Tuan'!$B:$B,$B18,'02_KH Thang_Tuan'!$J:$J,"Đã duyệt")&"/"&COUNTIFS('02_KH Thang_Tuan'!$B:$B,$B18)) | AJ18: =IF($B18="","",COUNTIFS('03_Phat sinh'!$C:$C,$B18,'03_Phat sinh'!$M:$M,"<>Đã duyệt")) | AK18: =IF($B18="","",COUNTIFS('04_CU dac thu'!$C:$C,$B18,'04_CU dac thu'!$N:$N,"<>Đã duyệt")) | AL18: =IF($B18="","",COUNTIFS('05_Bu tien do'!$B:$B,$B18,'05_Bu tien do'!$N:$N,"<>Đã hoàn thành"))
A19: 2.7 | C19: HM lớn | E19: Thi công cửa nhôm kính | U19: =IF(OR(I19="",T19=""),"",T19/I19) | Z19: =IF($B19="","",IF(AND(OR(K19="Đã phát hành",K19="Hoàn thiện"),M19="Đã bàn giao"),"✔","✘")) | AA19: =IF($B19="","",IF(Q19="Đã CU","✔","✘")) | AB19: =IF($B19="","",IF(Y19="Đã duyệt","✔","✘")) | AC19: =IF($B19="","",IF(AND(Z19="✔",AA19="✔",AB19="✔"),"ĐỦ ĐK KHỞI CÔNG","THIẾU ĐK")) | AE19: =IF($B19="","",COUNTIFS('01_HSo TienKC'!$B:$B,$B19,'01_HSo TienKC'!$J:$J,"Đã duyệt")) | AI19: =IF($B19="","",COUNTIFS('02_KH Thang_Tuan'!$B:$B,$B19,'02_KH Thang_Tuan'!$J:$J,"Đã duyệt")&"/"&COUNTIFS('02_KH Thang_Tuan'!$B:$B,$B19)) | AJ19: =IF($B19="","",COUNTIFS('03_Phat sinh'!$C:$C,$B19,'03_Phat sinh'!$M:$M,"<>Đã duyệt")) | AK19: =IF($B19="","",COUNTIFS('04_CU dac thu'!$C:$C,$B19,'04_CU dac thu'!$N:$N,"<>Đã duyệt")) | AL19: =IF($B19="","",COUNTIFS('05_Bu tien do'!$B:$B,$B19,'05_Bu tien do'!$N:$N,"<>Đã hoàn thành"))
A20: 2.8 | C20: HM lớn | E20: Thi công ốp lát mặt ngoài | U20: =IF(OR(I20="",T20=""),"",T20/I20) | Z20: =IF($B20="","",IF(AND(OR(K20="Đã phát hành",K20="Hoàn thiện"),M20="Đã bàn giao"),"✔","✘")) | AA20: =IF($B20="","",IF(Q20="Đã CU","✔","✘")) | AB20: =IF($B20="","",IF(Y20="Đã duyệt","✔","✘")) | AC20: =IF($B20="","",IF(AND(Z20="✔",AA20="✔",AB20="✔"),"ĐỦ ĐK KHỞI CÔNG","THIẾU ĐK")) | AE20: =IF($B20="","",COUNTIFS('01_HSo TienKC'!$B:$B,$B20,'01_HSo TienKC'!$J:$J,"Đã duyệt")) | AI20: =IF($B20="","",COUNTIFS('02_KH Thang_Tuan'!$B:$B,$B20,'02_KH Thang_Tuan'!$J:$J,"Đã duyệt")&"/"&COUNTIFS('02_KH Thang_Tuan'!$B:$B,$B20)) | AJ20: =IF($B20="","",COUNTIFS('03_Phat sinh'!$C:$C,$B20,'03_Phat sinh'!$M:$M,"<>Đã duyệt")) | AK20: =IF($B20="","",COUNTIFS('04_CU dac thu'!$C:$C,$B20,'04_CU dac thu'!$N:$N,"<>Đã duyệt")) | AL20: =IF($B20="","",COUNTIFS('05_Bu tien do'!$B:$B,$B20,'05_Bu tien do'!$N:$N,"<>Đã hoàn thành"))
A21: 2.9 | C21: HM lớn | E21: Thi công hệ thống M&E (điện, nước…) | U21: =IF(OR(I21="",T21=""),"",T21/I21) | Z21: =IF($B21="","",IF(AND(OR(K21="Đã phát hành",K21="Hoàn thiện"),M21="Đã bàn giao"),"✔","✘")) | AA21: =IF($B21="","",IF(Q21="Đã CU","✔","✘")) | AB21: =IF($B21="","",IF(Y21="Đã duyệt","✔","✘")) | AC21: =IF($B21="","",IF(AND(Z21="✔",AA21="✔",AB21="✔"),"ĐỦ ĐK KHỞI CÔNG","THIẾU ĐK")) | AE21: =IF($B21="","",COUNTIFS('01_HSo TienKC'!$B:$B,$B21,'01_HSo TienKC'!$J:$J,"Đã duyệt")) | AI21: =IF($B21="","",COUNTIFS('02_KH Thang_Tuan'!$B:$B,$B21,'02_KH Thang_Tuan'!$J:$J,"Đã duyệt")&"/"&COUNTIFS('02_KH Thang_Tuan'!$B:$B,$B21)) | AJ21: =IF($B21="","",COUNTIFS('03_Phat sinh'!$C:$C,$B21,'03_Phat sinh'!$M:$M,"<>Đã duyệt")) | AK21: =IF($B21="","",COUNTIFS('04_CU dac thu'!$C:$C,$B21,'04_CU dac thu'!$N:$N,"<>Đã duyệt")) | AL21: =IF($B21="","",COUNTIFS('05_Bu tien do'!$B:$B,$B21,'05_Bu tien do'!$N:$N,"<>Đã hoàn thành"))
A22: 2.10 | C22: HM lớn | E22: Thi công cảnh quan mặt ngoài | U22: =IF(OR(I22="",T22=""),"",T22/I22) | Z22: =IF($B22="","",IF(AND(OR(K22="Đã phát hành",K22="Hoàn thiện"),M22="Đã bàn giao"),"✔","✘")) | AA22: =IF($B22="","",IF(Q22="Đã CU","✔","✘")) | AB22: =IF($B22="","",IF(Y22="Đã duyệt","✔","✘")) | AC22: =IF($B22="","",IF(AND(Z22="✔",AA22="✔",AB22="✔"),"ĐỦ ĐK KHỞI CÔNG","THIẾU ĐK")) | AE22: =IF($B22="","",COUNTIFS('01_HSo TienKC'!$B:$B,$B22,'01_HSo TienKC'!$J:$J,"Đã duyệt")) | AI22: =IF($B22="","",COUNTIFS('02_KH Thang_Tuan'!$B:$B,$B22,'02_KH Thang_Tuan'!$J:$J,"Đã duyệt")&"/"&COUNTIFS('02_KH Thang_Tuan'!$B:$B,$B22)) | AJ22: =IF($B22="","",COUNTIFS('03_Phat sinh'!$C:$C,$B22,'03_Phat sinh'!$M:$M,"<>Đã duyệt")) | AK22: =IF($B22="","",COUNTIFS('04_CU dac thu'!$C:$C,$B22,'04_CU dac thu'!$N:$N,"<>Đã duyệt")) | AL22: =IF($B22="","",COUNTIFS('05_Bu tien do'!$B:$B,$B22,'05_Bu tien do'!$N:$N,"<>Đã hoàn thành"))
A23: 2.11 | C23: HM lớn | E23: Cung cấp lắp đặt chiếu sáng mặt ngoài | U23: =IF(OR(I23="",T23=""),"",T23/I23) | Z23: =IF($B23="","",IF(AND(OR(K23="Đã phát hành",K23="Hoàn thiện"),M23="Đã bàn giao"),"✔","✘")) | AA23: =IF($B23="","",IF(Q23="Đã CU","✔","✘")) | AB23: =IF($B23="","",IF(Y23="Đã duyệt","✔","✘")) | AC23: =IF($B23="","",IF(AND(Z23="✔",AA23="✔",AB23="✔"),"ĐỦ ĐK KHỞI CÔNG","THIẾU ĐK")) | AE23: =IF($B23="","",COUNTIFS('01_HSo TienKC'!$B:$B,$B23,'01_HSo TienKC'!$J:$J,"Đã duyệt")) | AI23: =IF($B23="","",COUNTIFS('02_KH Thang_Tuan'!$B:$B,$B23,'02_KH Thang_Tuan'!$J:$J,"Đã duyệt")&"/"&COUNTIFS('02_KH Thang_Tuan'!$B:$B,$B23)) | AJ23: =IF($B23="","",COUNTIFS('03_Phat sinh'!$C:$C,$B23,'03_Phat sinh'!$M:$M,"<>Đã duyệt")) | AK23: =IF($B23="","",COUNTIFS('04_CU dac thu'!$C:$C,$B23,'04_CU dac thu'!$N:$N,"<>Đã duyệt")) | AL23: =IF($B23="","",COUNTIFS('05_Bu tien do'!$B:$B,$B23,'05_Bu tien do'!$N:$N,"<>Đã hoàn thành"))
A24: 2.12 | C24: HM lớn | E24: Thi công bể bơi | U24: =IF(OR(I24="",T24=""),"",T24/I24) | Z24: =IF($B24="","",IF(AND(OR(K24="Đã phát hành",K24="Hoàn thiện"),M24="Đã bàn giao"),"✔","✘")) | AA24: =IF($B24="","",IF(Q24="Đã CU","✔","✘")) | AB24: =IF($B24="","",IF(Y24="Đã duyệt","✔","✘")) | AC24: =IF($B24="","",IF(AND(Z24="✔",AA24="✔",AB24="✔"),"ĐỦ ĐK KHỞI CÔNG","THIẾU ĐK")) | AE24: =IF($B24="","",COUNTIFS('01_HSo TienKC'!$B:$B,$B24,'01_HSo TienKC'!$J:$J,"Đã duyệt")) | AI24: =IF($B24="","",COUNTIFS('02_KH Thang_Tuan'!$B:$B,$B24,'02_KH Thang_Tuan'!$J:$J,"Đã duyệt")&"/"&COUNTIFS('02_KH Thang_Tuan'!$B:$B,$B24)) | AJ24: =IF($B24="","",COUNTIFS('03_Phat sinh'!$C:$C,$B24,'03_Phat sinh'!$M:$M,"<>Đã duyệt")) | AK24: =IF($B24="","",COUNTIFS('04_CU dac thu'!$C:$C,$B24,'04_CU dac thu'!$N:$N,"<>Đã duyệt")) | AL24: =IF($B24="","",COUNTIFS('05_Bu tien do'!$B:$B,$B24,'05_Bu tien do'!$N:$N,"<>Đã hoàn thành"))
A25: 2.13 | C25: HM lớn | E25: Thi công nội thất liền tường, rời | U25: =IF(OR(I25="",T25=""),"",T25/I25) | Z25: =IF($B25="","",IF(AND(OR(K25="Đã phát hành",K25="Hoàn thiện"),M25="Đã bàn giao"),"✔","✘")) | AA25: =IF($B25="","",IF(Q25="Đã CU","✔","✘")) | AB25: =IF($B25="","",IF(Y25="Đã duyệt","✔","✘")) | AC25: =IF($B25="","",IF(AND(Z25="✔",AA25="✔",AB25="✔"),"ĐỦ ĐK KHỞI CÔNG","THIẾU ĐK")) | AE25: =IF($B25="","",COUNTIFS('01_HSo TienKC'!$B:$B,$B25,'01_HSo TienKC'!$J:$J,"Đã duyệt")) | AI25: =IF($B25="","",COUNTIFS('02_KH Thang_Tuan'!$B:$B,$B25,'02_KH Thang_Tuan'!$J:$J,"Đã duyệt")&"/"&COUNTIFS('02_KH Thang_Tuan'!$B:$B,$B25)) | AJ25: =IF($B25="","",COUNTIFS('03_Phat sinh'!$C:$C,$B25,'03_Phat sinh'!$M:$M,"<>Đã duyệt")) | AK25: =IF($B25="","",COUNTIFS('04_CU dac thu'!$C:$C,$B25,'04_CU dac thu'!$N:$N,"<>Đã duyệt")) | AL25: =IF($B25="","",COUNTIFS('05_Bu tien do'!$B:$B,$B25,'05_Bu tien do'!$N:$N,"<>Đã hoàn thành"))
A26: 2.14 | C26: HM lớn | E26: Thi công lắp đặt thiết bị, trang trí nội thất | U26: =IF(OR(I26="",T26=""),"",T26/I26) | Z26: =IF($B26="","",IF(AND(OR(K26="Đã phát hành",K26="Hoàn thiện"),M26="Đã bàn giao"),"✔","✘")) | AA26: =IF($B26="","",IF(Q26="Đã CU","✔","✘")) | AB26: =IF($B26="","",IF(Y26="Đã duyệt","✔","✘")) | AC26: =IF($B26="","",IF(AND(Z26="✔",AA26="✔",AB26="✔"),"ĐỦ ĐK KHỞI CÔNG","THIẾU ĐK")) | AE26: =IF($B26="","",COUNTIFS('01_HSo TienKC'!$B:$B,$B26,'01_HSo TienKC'!$J:$J,"Đã duyệt")) | AI26: =IF($B26="","",COUNTIFS('02_KH Thang_Tuan'!$B:$B,$B26,'02_KH Thang_Tuan'!$J:$J,"Đã duyệt")&"/"&COUNTIFS('02_KH Thang_Tuan'!$B:$B,$B26)) | AJ26: =IF($B26="","",COUNTIFS('03_Phat sinh'!$C:$C,$B26,'03_Phat sinh'!$M:$M,"<>Đã duyệt")) | AK26: =IF($B26="","",COUNTIFS('04_CU dac thu'!$C:$C,$B26,'04_CU dac thu'!$N:$N,"<>Đã duyệt")) | AL26: =IF($B26="","",COUNTIFS('05_Bu tien do'!$B:$B,$B26,'05_Bu tien do'!$N:$N,"<>Đã hoàn thành"))
... A28: 2.16 | C28: HM lớn | E28: Thi công hệ thống smarthome | U28: =IF(OR(I28="",T28=""),"",T28/I28) | Z28: =IF($B28="","",IF(AND(OR(K28="Đã phát hành",K28="Hoàn thiện"),M28="Đã bàn giao"),"✔","✘")) | AA28: =IF($B28="","",IF(Q28="Đã CU","✔","✘")) | AB28: =IF($B28="","",IF(Y28="Đã duyệt","✔","✘")) | AC28: =IF($B28="","",IF(AND(Z28="✔",AA28="✔",AB28="✔"),"ĐỦ ĐK KHỞI CÔNG","THIẾU ĐK")) | AE28: =IF($B28="","",COUNTIFS('01_HSo TienKC'!$B:$B,$B28,'01_HSo TienKC'!$J:$J,"Đã duyệt")) | AI28: =IF($B28="","",COUNTIFS('02_KH Thang_Tuan'!$B:$B,$B28,'02_KH Thang_Tuan'!$J:$J,"Đã duyệt")&"/"&COUNTIFS('02_KH Thang_Tuan'!$B:$B,$B28)) | AJ28: =IF($B28="","",COUNTIFS('03_Phat sinh'!$C:$C,$B28,'03_Phat sinh'!$M:$M,"<>Đã duyệt")) | AK28: =IF($B28="","",COUNTIFS('04_CU dac thu'!$C:$C,$B28,'04_CU dac thu'!$N:$N,"<>Đã duyệt")) | AL28: =IF($B28="","",COUNTIFS('05_Bu tien do'!$B:$B,$B28,'05_Bu tien do'!$N:$N,"<>Đã hoàn thành"))
A29: 3 | B29: KD-PL21-01 | C29: PL21 | D29: Công trình phục vụ KD | E29: KD02 – Trung tâm TDTT (Bể bơi) | F29: HĐLCNT | G29: 46215 | H29: 46356 | I29: 12 | J29: 46142 | K29: Đã phát hành | L29: Đã cấp | M29: Đã bàn giao | N29: 46175 | O29: Đang đánh giá | P29: 46193 | Q29: Chưa CU | R29: 46204 | S29: Đang lập | U29: =IF(OR(I29="",T29=""),"",T29/I29) | W29: Chưa ký | Y29: Chưa trình | Z29: =IF($B29="","",IF(AND(OR(K29="Đã phát hành",K29="Hoàn thiện"),M29="Đã bàn giao"),"✔","✘")) -> ✔ | AA29: =IF($B29="","",IF(Q29="Đã CU","✔","✘")) -> ✘ | AB29: =IF($B29="","",IF(Y29="Đã duyệt","✔","✘")) -> ✘ | AC29: =IF($B29="","",IF(AND(Z29="✔",AA29="✔",AB29="✔"),"ĐỦ ĐK KHỞI CÔNG","THIẾU ĐK")) -> THIẾU ĐK | AE29: =IF($B29="","",COUNTIFS('01_HSo TienKC'!$B:$B,$B29,'01_HSo TienKC'!$J:$J,"Đã duyệt")) -> 0 | AI29: =IF($B29="","",COUNTIFS('02_KH Thang_Tuan'!$B:$B,$B29,'02_KH Thang_Tuan'!$J:$J,"Đã duyệt")&"/"&COUNTIFS('02_KH Thang_Tuan'!$B:$B,$B29)) -> 0/0 | AJ29: =IF($B29="","",COUNTIFS('03_Phat sinh'!$C:$C,$B29,'03_Phat sinh'!$M:$M,"<>Đã duyệt")) -> 0 | AK29: =IF($B29="","",COUNTIFS('04_CU dac thu'!$C:$C,$B29,'04_CU dac thu'!$N:$N,"<>Đã duyệt")) -> 0 | AL29: =IF($B29="","",COUNTIFS('05_Bu tien do'!$B:$B,$B29,'05_Bu tien do'!$N:$N,"<>Đã hoàn thành")) -> 0
U30: =IF(OR(I30="",T30=""),"",T30/I30) | Z30: =IF($B30="","",IF(AND(OR(K30="Đã phát hành",K30="Hoàn thiện"),M30="Đã bàn giao"),"✔","✘")) | AA30: =IF($B30="","",IF(Q30="Đã CU","✔","✘")) | AB30: =IF($B30="","",IF(Y30="Đã duyệt","✔","✘")) | AC30: =IF($B30="","",IF(AND(Z30="✔",AA30="✔",AB30="✔"),"ĐỦ ĐK KHỞI CÔNG","THIẾU ĐK")) | AE30: =IF($B30="","",COUNTIFS('01_HSo TienKC'!$B:$B,$B30,'01_HSo TienKC'!$J:$J,"Đã duyệt")) | AI30: =IF($B30="","",COUNTIFS('02_KH Thang_Tuan'!$B:$B,$B30,'02_KH Thang_Tuan'!$J:$J,"Đã duyệt")&"/"&COUNTIFS('02_KH Thang_Tuan'!$B:$B,$B30)) | AJ30: =IF($B30="","",COUNTIFS('03_Phat sinh'!$C:$C,$B30,'03_Phat sinh'!$M:$M,"<>Đã duyệt")) | AK30: =IF($B30="","",COUNTIFS('04_CU dac thu'!$C:$C,$B30,'04_CU dac thu'!$N:$N,"<>Đã duyệt")) | AL30: =IF($B30="","",COUNTIFS('05_Bu tien do'!$B:$B,$B30,'05_Bu tien do'!$N:$N,"<>Đã hoàn thành"))
U31: =IF(OR(I31="",T31=""),"",T31/I31) | Z31: =IF($B31="","",IF(AND(OR(K31="Đã phát hành",K31="Hoàn thiện"),M31="Đã bàn giao"),"✔","✘")) | AA31: =IF($B31="","",IF(Q31="Đã CU","✔","✘")) | AB31: =IF($B31="","",IF(Y31="Đã duyệt","✔","✘")) | AC31: =IF($B31="","",IF(AND(Z31="✔",AA31="✔",AB31="✔"),"ĐỦ ĐK KHỞI CÔNG","THIẾU ĐK")) | AE31: =IF($B31="","",COUNTIFS('01_HSo TienKC'!$B:$B,$B31,'01_HSo TienKC'!$J:$J,"Đã duyệt")) | AI31: =IF($B31="","",COUNTIFS('02_KH Thang_Tuan'!$B:$B,$B31,'02_KH Thang_Tuan'!$J:$J,"Đã duyệt")&"/"&COUNTIFS('02_KH Thang_Tuan'!$B:$B,$B31)) | AJ31: =IF($B31="","",COUNTIFS('03_Phat sinh'!$C:$C,$B31,'03_Phat sinh'!$M:$M,"<>Đã duyệt")) | AK31: =IF($B31="","",COUNTIFS('04_CU dac thu'!$C:$C,$B31,'04_CU dac thu'!$N:$N,"<>Đã duyệt")) | AL31: =IF($B31="","",COUNTIFS('05_Bu tien do'!$B:$B,$B31,'05_Bu tien do'!$N:$N,"<>Đã hoàn thành"))
U32: =IF(OR(I32="",T32=""),"",T32/I32) | Z32: =IF($B32="","",IF(AND(OR(K32="Đã phát hành",K32="Hoàn thiện"),M32="Đã bàn giao"),"✔","✘")) | AA32: =IF($B32="","",IF(Q32="Đã CU","✔","✘")) | AB32: =IF($B32="","",IF(Y32="Đã duyệt","✔","✘")) | AC32: =IF($B32="","",IF(AND(Z32="✔",AA32="✔",AB32="✔"),"ĐỦ ĐK KHỞI CÔNG","THIẾU ĐK")) | AE32: =IF($B32="","",COUNTIFS('01_HSo TienKC'!$B:$B,$B32,'01_HSo TienKC'!$J:$J,"Đã duyệt")) | AI32: =IF($B32="","",COUNTIFS('02_KH Thang_Tuan'!$B:$B,$B32,'02_KH Thang_Tuan'!$J:$J,"Đã duyệt")&"/"&COUNTIFS('02_KH Thang_Tuan'!$B:$B,$B32)) | AJ32: =IF($B32="","",COUNTIFS('03_Phat sinh'!$C:$C,$B32,'03_Phat sinh'!$M:$M,"<>Đã duyệt")) | AK32: =IF($B32="","",COUNTIFS('04_CU dac thu'!$C:$C,$B32,'04_CU dac thu'!$N:$N,"<>Đã duyệt")) | AL32: =IF($B32="","",COUNTIFS('05_Bu tien do'!$B:$B,$B32,'05_Bu tien do'!$N:$N,"<>Đã hoàn thành"))
U33: =IF(OR(I33="",T33=""),"",T33/I33) | Z33: =IF($B33="","",IF(AND(OR(K33="Đã phát hành",K33="Hoàn thiện"),M33="Đã bàn giao"),"✔","✘")) | AA33: =IF($B33="","",IF(Q33="Đã CU","✔","✘")) | AB33: =IF($B33="","",IF(Y33="Đã duyệt","✔","✘")) | AC33: =IF($B33="","",IF(AND(Z33="✔",AA33="✔",AB33="✔"),"ĐỦ ĐK KHỞI CÔNG","THIẾU ĐK")) | AE33: =IF($B33="","",COUNTIFS('01_HSo TienKC'!$B:$B,$B33,'01_HSo TienKC'!$J:$J,"Đã duyệt")) | AI33: =IF($B33="","",COUNTIFS('02_KH Thang_Tuan'!$B:$B,$B33,'02_KH Thang_Tuan'!$J:$J,"Đã duyệt")&"/"&COUNTIFS('02_KH Thang_Tuan'!$B:$B,$B33)) | AJ33: =IF($B33="","",COUNTIFS('03_Phat sinh'!$C:$C,$B33,'03_Phat sinh'!$M:$M,"<>Đã duyệt")) | AK33: =IF($B33="","",COUNTIFS('04_CU dac thu'!$C:$C,$B33,'04_CU dac thu'!$N:$N,"<>Đã duyệt")) | AL33: =IF($B33="","",COUNTIFS('05_Bu tien do'!$B:$B,$B33,'05_Bu tien do'!$N:$N,"<>Đã hoàn thành"))
U34: =IF(OR(I34="",T34=""),"",T34/I34) | Z34: =IF($B34="","",IF(AND(OR(K34="Đã phát hành",K34="Hoàn thiện"),M34="Đã bàn giao"),"✔","✘")) | AA34: =IF($B34="","",IF(Q34="Đã CU","✔","✘")) | AB34: =IF($B34="","",IF(Y34="Đã duyệt","✔","✘")) | AC34: =IF($B34="","",IF(AND(Z34="✔",AA34="✔",AB34="✔"),"ĐỦ ĐK KHỞI CÔNG","THIẾU ĐK")) | AE34: =IF($B34="","",COUNTIFS('01_HSo TienKC'!$B:$B,$B34,'01_HSo TienKC'!$J:$J,"Đã duyệt")) | AI34: =IF($B34="","",COUNTIFS('02_KH Thang_Tuan'!$B:$B,$B34,'02_KH Thang_Tuan'!$J:$J,"Đã duyệt")&"/"&COUNTIFS('02_KH Thang_Tuan'!$B:$B,$B34)) | AJ34: =IF($B34="","",COUNTIFS('03_Phat sinh'!$C:$C,$B34,'03_Phat sinh'!$M:$M,"<>Đã duyệt")) | AK34: =IF($B34="","",COUNTIFS('04_CU dac thu'!$C:$C,$B34,'04_CU dac thu'!$N:$N,"<>Đã duyệt")) | AL34: =IF($B34="","",COUNTIFS('05_Bu tien do'!$B:$B,$B34,'05_Bu tien do'!$N:$N,"<>Đã hoàn thành"))
U35: =IF(OR(I35="",T35=""),"",T35/I35) | Z35: =IF($B35="","",IF(AND(OR(K35="Đã phát hành",K35="Hoàn thiện"),M35="Đã bàn giao"),"✔","✘")) | AA35: =IF($B35="","",IF(Q35="Đã CU","✔","✘")) | AB35: =IF($B35="","",IF(Y35="Đã duyệt","✔","✘")) | AC35: =IF($B35="","",IF(AND(Z35="✔",AA35="✔",AB35="✔"),"ĐỦ ĐK KHỞI CÔNG","THIẾU ĐK")) | AE35: =IF($B35="","",COUNTIFS('01_HSo TienKC'!$B:$B,$B35,'01_HSo TienKC'!$J:$J,"Đã duyệt")) | AI35: =IF($B35="","",COUNTIFS('02_KH Thang_Tuan'!$B:$B,$B35,'02_KH Thang_Tuan'!$J:$J,"Đã duyệt")&"/"&COUNTIFS('02_KH Thang_Tuan'!$B:$B,$B35)) | AJ35: =IF($B35="","",COUNTIFS('03_Phat sinh'!$C:$C,$B35,'03_Phat sinh'!$M:$M,"<>Đã duyệt")) | AK35: =IF($B35="","",COUNTIFS('04_CU dac thu'!$C:$C,$B35,'04_CU dac thu'!$N:$N,"<>Đã duyệt")) | AL35: =IF($B35="","",COUNTIFS('05_Bu tien do'!$B:$B,$B35,'05_Bu tien do'!$N:$N,"<>Đã hoàn thành"))
U36: =IF(OR(I36="",T36=""),"",T36/I36) | Z36: =IF($B36="","",IF(AND(OR(K36="Đã phát hành",K36="Hoàn thiện"),M36="Đã bàn giao"),"✔","✘")) | AA36: =IF($B36="","",IF(Q36="Đã CU","✔","✘")) | AB36: =IF($B36="","",IF(Y36="Đã duyệt","✔","✘")) | AC36: =IF($B36="","",IF(AND(Z36="✔",AA36="✔",AB36="✔"),"ĐỦ ĐK KHỞI CÔNG","THIẾU ĐK")) | AE36: =IF($B36="","",COUNTIFS('01_HSo TienKC'!$B:$B,$B36,'01_HSo TienKC'!$J:$J,"Đã duyệt")) | AI36: =IF($B36="","",COUNTIFS('02_KH Thang_Tuan'!$B:$B,$B36,'02_KH Thang_Tuan'!$J:$J,"Đã duyệt")&"/"&COUNTIFS('02_KH Thang_Tuan'!$B:$B,$B36)) | AJ36: =IF($B36="","",COUNTIFS('03_Phat sinh'!$C:$C,$B36,'03_Phat sinh'!$M:$M,"<>Đã duyệt")) | AK36: =IF($B36="","",COUNTIFS('04_CU dac thu'!$C:$C,$B36,'04_CU dac thu'!$N:$N,"<>Đã duyệt")) | AL36: =IF($B36="","",COUNTIFS('05_Bu tien do'!$B:$B,$B36,'05_Bu tien do'!$N:$N,"<>Đã hoàn thành"))
U37: =IF(OR(I37="",T37=""),"",T37/I37) | Z37: =IF($B37="","",IF(AND(OR(K37="Đã phát hành",K37="Hoàn thiện"),M37="Đã bàn giao"),"✔","✘")) | AA37: =IF($B37="","",IF(Q37="Đã CU","✔","✘")) | AB37: =IF($B37="","",IF(Y37="Đã duyệt","✔","✘")) | AC37: =IF($B37="","",IF(AND(Z37="✔",AA37="✔",AB37="✔"),"ĐỦ ĐK KHỞI CÔNG","THIẾU ĐK")) | AE37: =IF($B37="","",COUNTIFS('01_HSo TienKC'!$B:$B,$B37,'01_HSo TienKC'!$J:$J,"Đã duyệt")) | AI37: =IF($B37="","",COUNTIFS('02_KH Thang_Tuan'!$B:$B,$B37,'02_KH Thang_Tuan'!$J:$J,"Đã duyệt")&"/"&COUNTIFS('02_KH Thang_Tuan'!$B:$B,$B37)) | AJ37: =IF($B37="","",COUNTIFS('03_Phat sinh'!$C:$C,$B37,'03_Phat sinh'!$M:$M,"<>Đã duyệt")) | AK37: =IF($B37="","",COUNTIFS('04_CU dac thu'!$C:$C,$B37,'04_CU dac thu'!$N:$N,"<>Đã duyệt")) | AL37: =IF($B37="","",COUNTIFS('05_Bu tien do'!$B:$B,$B37,'05_Bu tien do'!$N:$N,"<>Đã hoàn thành"))
U38: =IF(OR(I38="",T38=""),"",T38/I38) | Z38: =IF($B38="","",IF(AND(OR(K38="Đã phát hành",K38="Hoàn thiện"),M38="Đã bàn giao"),"✔","✘")) | AA38: =IF($B38="","",IF(Q38="Đã CU","✔","✘")) | AB38: =IF($B38="","",IF(Y38="Đã duyệt","✔","✘")) | AC38: =IF($B38="","",IF(AND(Z38="✔",AA38="✔",AB38="✔"),"ĐỦ ĐK KHỞI CÔNG","THIẾU ĐK")) | AE38: =IF($B38="","",COUNTIFS('01_HSo TienKC'!$B:$B,$B38,'01_HSo TienKC'!$J:$J,"Đã duyệt")) | AI38: =IF($B38="","",COUNTIFS('02_KH Thang_Tuan'!$B:$B,$B38,'02_KH Thang_Tuan'!$J:$J,"Đã duyệt")&"/"&COUNTIFS('02_KH Thang_Tuan'!$B:$B,$B38)) | AJ38: =IF($B38="","",COUNTIFS('03_Phat sinh'!$C:$C,$B38,'03_Phat sinh'!$M:$M,"<>Đã duyệt")) | AK38: =IF($B38="","",COUNTIFS('04_CU dac thu'!$C:$C,$B38,'04_CU dac thu'!$N:$N,"<>Đã duyệt")) | AL38: =IF($B38="","",COUNTIFS('05_Bu tien do'!$B:$B,$B38,'05_Bu tien do'!$N:$N,"<>Đã hoàn thành"))
U39: =IF(OR(I39="",T39=""),"",T39/I39) | Z39: =IF($B39="","",IF(AND(OR(K39="Đã phát hành",K39="Hoàn thiện"),M39="Đã bàn giao"),"✔","✘")) | AA39: =IF($B39="","",IF(Q39="Đã CU","✔","✘")) | AB39: =IF($B39="","",IF(Y39="Đã duyệt","✔","✘")) | AC39: =IF($B39="","",IF(AND(Z39="✔",AA39="✔",AB39="✔"),"ĐỦ ĐK KHỞI CÔNG","THIẾU ĐK")) | AE39: =IF($B39="","",COUNTIFS('01_HSo TienKC'!$B:$B,$B39,'01_HSo TienKC'!$J:$J,"Đã duyệt")) | AI39: =IF($B39="","",COUNTIFS('02_KH Thang_Tuan'!$B:$B,$B39,'02_KH Thang_Tuan'!$J:$J,"Đã duyệt")&"/"&COUNTIFS('02_KH Thang_Tuan'!$B:$B,$B39)) | AJ39: =IF($B39="","",COUNTIFS('03_Phat sinh'!$C:$C,$B39,'03_Phat sinh'!$M:$M,"<>Đã duyệt")) | AK39: =IF($B39="","",COUNTIFS('04_CU dac thu'!$C:$C,$B39,'04_CU dac thu'!$N:$N,"<>Đã duyệt")) | AL39: =IF($B39="","",COUNTIFS('05_Bu tien do'!$B:$B,$B39,'05_Bu tien do'!$N:$N,"<>Đã hoàn thành"))
U40: =IF(OR(I40="",T40=""),"",T40/I40) | Z40: =IF($B40="","",IF(AND(OR(K40="Đã phát hành",K40="Hoàn thiện"),M40="Đã bàn giao"),"✔","✘")) | AA40: =IF($B40="","",IF(Q40="Đã CU","✔","✘")) | AB40: =IF($B40="","",IF(Y40="Đã duyệt","✔","✘")) | AC40: =IF($B40="","",IF(AND(Z40="✔",AA40="✔",AB40="✔"),"ĐỦ ĐK KHỞI CÔNG","THIẾU ĐK")) | AE40: =IF($B40="","",COUNTIFS('01_HSo TienKC'!$B:$B,$B40,'01_HSo TienKC'!$J:$J,"Đã duyệt")) | AI40: =IF($B40="","",COUNTIFS('02_KH Thang_Tuan'!$B:$B,$B40,'02_KH Thang_Tuan'!$J:$J,"Đã duyệt")&"/"&COUNTIFS('02_KH Thang_Tuan'!$B:$B,$B40)) | AJ40: =IF($B40="","",COUNTIFS('03_Phat sinh'!$C:$C,$B40,'03_Phat sinh'!$M:$M,"<>Đã duyệt")) | AK40: =IF($B40="","",COUNTIFS('04_CU dac thu'!$C:$C,$B40,'04_CU dac thu'!$N:$N,"<>Đã duyệt")) | AL40: =IF($B40="","",COUNTIFS('05_Bu tien do'!$B:$B,$B40,'05_Bu tien do'!$N:$N,"<>Đã hoàn thành"))
U41: =IF(OR(I41="",T41=""),"",T41/I41) | Z41: =IF($B41="","",IF(AND(OR(K41="Đã phát hành",K41="Hoàn thiện"),M41="Đã bàn giao"),"✔","✘")) | AA41: =IF($B41="","",IF(Q41="Đã CU","✔","✘")) | AB41: =IF($B41="","",IF(Y41="Đã duyệt","✔","✘")) | AC41: =IF($B41="","",IF(AND(Z41="✔",AA41="✔",AB41="✔"),"ĐỦ ĐK KHỞI CÔNG","THIẾU ĐK")) | AE41: =IF($B41="","",COUNTIFS('01_HSo TienKC'!$B:$B,$B41,'01_HSo TienKC'!$J:$J,"Đã duyệt")) | AI41: =IF($B41="","",COUNTIFS('02_KH Thang_Tuan'!$B:$B,$B41,'02_KH Thang_Tuan'!$J:$J,"Đã duyệt")&"/"&COUNTIFS('02_KH Thang_Tuan'!$B:$B,$B41)) | AJ41: =IF($B41="","",COUNTIFS('03_Phat sinh'!$C:$C,$B41,'03_Phat sinh'!$M:$M,"<>Đã duyệt")) | AK41: =IF($B41="","",COUNTIFS('04_CU dac thu'!$C:$C,$B41,'04_CU dac thu'!$N:$N,"<>Đã duyệt")) | AL41: =IF($B41="","",COUNTIFS('05_Bu tien do'!$B:$B,$B41,'05_Bu tien do'!$N:$N,"<>Đã hoàn thành"))
...

Sheet 01_HSo TienKC
A1: SỔ 01 – HỒ SƠ TIỀN KHỞI CÔNG (lưu link sản phẩm các bước đã hoàn thành)
A2: STT | B2: Mã BSC | C2: Hạng mục | D2: Loại hồ sơ | E2: Tên sản phẩm / Số hiệu | F2: LINK lưu trữ | G2: Ngày HT | H2: Người lập | I2: Người duyệt | J2: TT duyệt
A3: 1 | B3: VSV_QLTC_TT.01 | C3: CT-01 Nhà mẫu | D3: HSTKTC | E3: BVTC Nhà mẫu CT-01 Rev.B | F3: BVTC_CT01_RevB.pdf | G3: 46162 | H3: TVTK | I3: CĐT | J3: Đã duyệt
A4: 2 | B4: VSV_QLTC_TT.01 | C4: CT-01 Nhà mẫu | D4: SPECS | E4: Chỉ dẫn kỹ thuật CT-01 | F4: SPECS_CT01.pdf | G4: 46162 | H4: TVTK | I4: CĐT | J4: Đã duyệt
A5: 3 | B5: VSV_QLTC_TT.01 | C5: CT-01 Nhà mẫu | D5: BOQ/KL | E5: BOQ CT-01 (PL10) | F5: BOQ_CT01_PL10.xlsx | G5: 46162 | H5: TVTK | I5: CĐT | J5: Đã duyệt
A6: 4 | B6: VSV_QLTC_TT.01 | C6: CT-01 Nhà mẫu | D6: KQ LCNT | E6: QĐ phê duyệt KQ LCNT CT-01 | F6: QD_KQLCNT_CT01.pdf | G6: 46160 | H6: HĐLCNT | I6: CĐT | J6: Đã duyệt
A7: 5 | B7: VSV_QLTC_TT.01 | C7: CT-01 Nhà mẫu | D7: HĐCU | E7: HĐ cung ứng CT-01 số 12/2026 | F7: HDCU_CT01_12.pdf | G7: 46162 | H7: P.KTKH | I7: CĐT | J7: Đã duyệt
A8: 6 | B8: VSV_QLTC_TT.01 | C8: CT-01 Nhà mẫu | D8: PD KHCU | E8: QĐ duyệt KH cung ứng CT-01 | F8: QD_KHCU_CT01.pdf | G8: 46167 | H8: Tổng thầu | I8: CĐT | J8: Đã duyệt
A9: 7 | B9: VSV_QLTC_TT.01 | C9: CT-01 Nhà mẫu | D9: Ký PLHĐ | E9: PLHĐ CĐT–Tổng thầu CT-01 | F9: PLHD_CT01.pdf | G9: 46164 | H9: P.KTKH | I9: CĐT | J9: Đã duyệt
A10: 8 | B10: VSV_QLTC_TT.01 | C10: CT-01 Nhà mẫu | D10: PD KHTK | E10: QĐ duyệt KHTK CT-01 | F10: QD_KHTK_CT01.pdf | G10: 46170 | H10: Tổng thầu | I10: CĐT | J10: Đã duyệt
A11: 9 | B11: HT-PL02-01 | C11: HTKT quanh CV | D11: HSTKTC | E11: BVTC HTKT quanh CV Rev.A | F11: BVTC_HT_PL02.pdf | G11: 45631 | H11: TVTK | I11: CĐT | J11: Đã duyệt
A12: 10 | B12: HT-PL02-01 | C12: HTKT quanh CV | D12: SPECS | E12: Chỉ dẫn KT HTKT | F12: SPECS_HT.pdf | G12: 45631 | H12: TVTK | I12: CĐT | J12: Đã duyệt
A13: 11 | B13: HT-PL02-01 | C13: HTKT quanh CV | D13: BOQ/KL | E13: BOQ HTKT (PL02) | F13: BOQ_HT_PL02.xlsx | G13: 45631 | H13: TVTK | I13: CĐT | J13: Đã duyệt
A14: 12 | B14: HT-PL02-01 | C14: HTKT quanh CV | D14: KQ LCNT | E14: QĐ KQ LCNT HTKT | F14: QD_KQLCNT_HT.pdf | G14: 45631 | H14: TVTK | I14: CĐT | J14: Đã duyệt
... A18: 16 | B18: HT-PL02-01 | C18: HTKT quanh CV | D18: PD KHTK | E18: QĐ duyệt KHTK HTKT | F18: QD_KHTK_HT.pdf | G18: 45631 | H18: TVTK | I18: CĐT | J18: Đã duyệt

Sheet 02_KH Thang_Tuan
A1: SỔ 02 – KẾ HOẠCH TRIỂN KHAI THÁNG/TUẦN (tài liệu kèm theo, lập & duyệt)
A2: STT | B2: Mã BSC | C2: Hạng mục | D2: Tháng | E2: Loại tài liệu | F2: Nội dung chính | G2: Đạt YCKT CĐT | H2: LINK tài liệu | I2: TT lập | J2: TT duyệt | K2: Người lập | L2: Người duyệt | M2: Ngày duyệt
A3: 1 | B3: VSV_QLTC_TT.01 | C3: CT-01 Nhà mẫu | D3: 06/2026 | E3: Biện pháp thi công | F3: BPTC cọc & móng tháng 6 | G3: Có | H3: BPTC_CT01_T6.pdf | I3: Đã lập | J3: Đã duyệt | K3: Tổng thầu | L3: TVGS | M3: 46172
A4: 2 | B4: VSV_QLTC_TT.01 | C4: CT-01 Nhà mẫu | D4: 06/2026 | E4: Kế hoạch cung ứng | F4: KH cung ứng vật tư tháng 6 | G4: Có | H4: KHCU_CT01_T6.xlsx | I4: Đã lập | J4: Đã duyệt | K4: Tổng thầu | L4: CĐT | M4: 46172
A5: 3 | B5: VSV_QLTC_TT.01 | C5: CT-01 Nhà mẫu | D5: 06/2026 | E5: Biểu đồ nhân lực | F5: Biểu đồ nhân lực tháng 6 | G5: Có | H5: BĐ_NhanLuc_T6.pdf | I5: Đã lập | J5: Đã duyệt | K5: Tổng thầu | L5: TVGS | M5: 46173
A6: 4 | B6: VSV_QLTC_TT.01 | C6: CT-01 Nhà mẫu | D6: 06/2026 | E6: Biểu đồ máy móc thiết bị | F6: Biểu đồ thiết bị tháng 6 | G6: Có | H6: BĐ_ThietBi_T6.pdf | I6: Đã lập | J6: Chờ duyệt | K6: Tổng thầu
A7: 5 | B7: VSV_QLTC_TT.01 | C7: CT-01 Nhà mẫu | D7: 06/2026 | E7: Biểu đồ cung ứng | F7: Biểu đồ cung ứng VT tháng 6 | G7: Có | H7: BĐ_CungUng_T6.pdf | I7: Đã lập | J7: Đã duyệt | K7: Tổng thầu | L7: CĐT | M7: 46173

Sheet 03_Phat sinh
A1: SỔ 03 – PHÁT SINH & SAI KHÁC (làm rõ – ghi nhận – phê duyệt – cập nhật điều chỉnh)
A2: STT | B2: Mã PS | C2: Mã BSC | D2: Hạng mục | E2: Ngày PS | F2: Loại | G2: Mô tả | H2: Nguyên nhân | I2: Đề xuất xử lý | J2: Giá trị (tỷ) | K2: Ảnh hưởng TĐ (ngày) | L2: LINK hồ sơ | M2: TT duyệt | N2: Người duyệt | O2: Ngày duyệt | P2: Nội dung điều chỉnh (KH→KQ) | Q2: Ghi chú
A3: 1 | B3: PS.CT01.01 | C3: VSV_QLTC_TT.01 | D3: Móng nhà mẫu | E3: 46185 | F3: Phát sinh khối lượng | G3: Gặp nền đất yếu cục bộ, tăng KL xử lý nền | H3: Địa chất khác hồ sơ khảo sát | I3: Bổ sung cọc tre + thay nền cát | J3: 0.8 | K3: 5 | L3: PS01_NenYeu.pdf | M3: Chờ duyệt | P3: Cập nhật BPTC & dự toán bổ sung; điều chỉnh KH tuần 3-4
A4: 2 | B4: PS.CT01.02 | C4: VSV_QLTC_TT.01 | D4: Kết cấu thân T1 | E4: 46188 | F4: Sai khác thiết kế | G4: Cao độ dầm sàn lệch so bản vẽ | H4: Lỗi bản vẽ phối hợp | I4: RFI điều chỉnh, phát hành bản vẽ Rev.C | J4: 0 | K4: 0 | L4: PS02_RFI.pdf | M4: Đã duyệt | N4: TVTK | O4: 46190 | P4: Bản vẽ Rev.C đã phát hành, cập nhật KL

Sheet 04_CU dac thu
A1: SỔ 04 – CUNG ỨNG ĐẶC THÙ / ĐỘT XUẤT (ghi nhận – phê duyệt – kiểm soát)
A2: STT | B2: Mã YC | C2: Mã BSC | D2: Hạng mục | E2: Ngày YC | F2: Loại YC | G2: Vật tư / Thiết bị | H2: Đặc tả KT / Lý do | I2: KL | J2: ĐVT | K2: Giá trị (tỷ) | L2: Trong/Ngoài HĐCU | M2: LINK hồ sơ | N2: TT duyệt | O2: Người duyệt | P2: Ngày cần | Q2: TT cung ứng | R2: Ghi chú
A3: 1 | B3: YC.CT01.01 | C3: VSV_QLTC_TT.01 | D3: Sảnh nhà mẫu | E3: 46187 | F3: Đặc thù | G3: Đá marble nhập khẩu ốp sảnh | H3: Theo yêu cầu thẩm mỹ CĐT, ngoài danh mục VT chuẩn | I3: 120 | J3: m2 | K3: 1.2 | L3: Ngoài HĐCU | M3: YC01_Marble.pdf | N3: Chờ duyệt | P3: 46213 | Q3: Chưa cung ứng
A4: 2 | B4: YC.CT01.02 | C4: VSV_QLTC_TT.01 | D4: Đổ bê tông móng | E4: 46183 | F4: Đột xuất | G4: Thuê bơm bê tông cần dài | H4: Mặt bằng chật, phát sinh đột xuất | I4: 1 | J4: ca | K4: 0.05 | L4: Trong HĐCU | M4: YC02_Bom.pdf | N4: Đã duyệt | O4: BĐH | P4: 46185 | Q4: Đã cung ứng

Sheet 05_Bu tien do
A1: SỔ 05 – BÙ TIẾN ĐỘ (chậm tiến độ: tăng ca / đổi BPTC / thêm nguồn lực)
A2: STT | B2: Mã BSC | C2: Hạng mục | D2: Ngày phát hiện | E2: Mức chậm (ngày) | F2: Nguyên nhân | G2: Giải pháp bù | H2: Chi tiết giải pháp | I2: Mốc cam kết HT | J2: LINK phương án | K2: TT duyệt | L2: Người duyệt | M2: KQ thực hiện bù | N2: TT thực hiện | O2: Ghi chú
A3: 1 | B3: VSV_QLTC_TT.01 | C3: Cọc + móng CT-01 | D3: 46189 | E3: 5 | F3: Mưa kéo dài + phát sinh nền yếu | G3: Tăng ca | H3: Tăng ca tối 2h/ngày, bổ sung 1 máy ép cọc, điều phối lại mũi thi công | I3: 46203 | J3: PA_BuTienDo_CT01.pdf | K3: Đã duyệt | L3: BĐH/CĐT | M3: Đang theo dõi, bù được 2/5 ngày | N3: Đang thực hiện

Sheet DM_Danh muc
A1: DANH MỤC CHUẨN (dropdown – có thể bổ sung, KHÔNG đổi tên cột)
A2: TT HSTKTC | B2: TT SPECS | C2: TT BOQ/KL | D2: TT LCNT | E2: TT Ký HĐCU | F2: TT KHCU | G2: TT Ký PLHĐ | H2: TT KHTK | I2: Mức độ | J2: Nhóm CT | K2: Cấp | L2: TT duyệt (chung) | M2: TT cung ứng | N2: TT bù tiến độ | O2: Loại hồ sơ tiền KC | P2: Loại tài liệu KH tháng | Q2: Loại phát sinh | R2: Loại YC cung ứng | S2: Giải pháp bù | T2: Đạt YCKT CĐT
A3: Chưa có TK | B3: Chưa có | C3: Chưa bàn giao | D3: Chưa LCNT | E3: Chưa CU | F3: Chưa lập | G3: Chưa ký | H3: Chưa trình | I3: Cao | J3: Hạ tầng kỹ thuật | K3: Gói thầu | L3: Chưa lập | M3: Chưa cung ứng | N3: Đang thực hiện | O3: HSTKTC | P3: Biện pháp thi công | Q3: Phát sinh khối lượng | R3: Đặc thù | S3: Tăng ca | T3: Có
A4: Đang TK | B4: Đang lập | C4: Đang lập | D4: Đang mời thầu | E4: Đang trình ký | F4: Đang lập | G4: Đang lập BPTC | H4: Đang duyệt | I4: Trung bình | J4: Xây dựng dân dụng | K4: HM lớn | L4: Đang lập | M4: Đang cung ứng | N4: Đã hoàn thành | O4: SPECS | P4: Kế hoạch cung ứng | Q4: Sai khác thiết kế | R4: Đột xuất | S4: Thêm nhân lực | T4: Không
A5: Điều chỉnh TK | B5: Đã cấp | C5: Điều chỉnh | D5: Đang đánh giá | E5: Đã CU | F5: Chờ duyệt | G5: Đã ký PLHĐ | H5: Đã duyệt | I5: Thấp | J5: Công trình phục vụ KD | K5: HM thành phần | L5: Chờ duyệt | M5: Đã cung ứng | N5: Đóng | O5: BOQ/KL | P5: Biểu đồ nhân lực | Q5: Thay đổi vật tư | S5: Thay đổi BPTC
A6: Đã phát hành | C6: Đã bàn giao | D6: Đã có KQ | E6: Theo đợt TC | F6: Đã duyệt | L6: Đã duyệt | O6: KQ LCNT | P6: Biểu đồ máy móc thiết bị | Q6: Thay đổi biện pháp | S6: Thêm thiết bị
A7: Hoàn thiện | D7: Đã ký | L7: Từ chối | O7: HĐCU | P7: Biểu đồ cung ứng | Q7: Khác | S7: Điều phối lại
O8: PD KHCU
O9: Ký PLHĐ
O10: PD KHTK
